2021-07-15 14:37:04,264 ERROR: Exception on /set_bookings [POST] [in /hdd/code/eastbournecottage/venv/lib/python3.8/site-packages/flask/app.py:1891]
Traceback (most recent call last):
  File "/hdd/code/eastbournecottage/venv/lib/python3.8/site-packages/sqlalchemy/engine/base.py", line 1277, in _execute_context
    self.dialect.do_execute(
  File "/hdd/code/eastbournecottage/venv/lib/python3.8/site-packages/sqlalchemy/engine/default.py", line 593, in do_execute
    cursor.execute(statement, parameters)
  File "/hdd/code/eastbournecottage/venv/lib/python3.8/site-packages/pymysql/cursors.py", line 163, in execute
    result = self._query(query)
  File "/hdd/code/eastbournecottage/venv/lib/python3.8/site-packages/pymysql/cursors.py", line 321, in _query
    conn.query(q)
  File "/hdd/code/eastbournecottage/venv/lib/python3.8/site-packages/pymysql/connections.py", line 505, in query
    self._affected_rows = self._read_query_result(unbuffered=unbuffered)
  File "/hdd/code/eastbournecottage/venv/lib/python3.8/site-packages/pymysql/connections.py", line 724, in _read_query_result
    result.read()
  File "/hdd/code/eastbournecottage/venv/lib/python3.8/site-packages/pymysql/connections.py", line 1069, in read
    first_packet = self.connection._read_packet()
  File "/hdd/code/eastbournecottage/venv/lib/python3.8/site-packages/pymysql/connections.py", line 676, in _read_packet
    packet.raise_for_error()
  File "/hdd/code/eastbournecottage/venv/lib/python3.8/site-packages/pymysql/protocol.py", line 223, in raise_for_error
    err.raise_mysql_exception(self._data)
  File "/hdd/code/eastbournecottage/venv/lib/python3.8/site-packages/pymysql/err.py", line 107, in raise_mysql_exception
    raise errorclass(errno, errval)
pymysql.err.DataError: (1265, "Data truncated for column 'invoice_status' at row 1")

The above exception was the direct cause of the following exception:

Traceback (most recent call last):
  File "/hdd/code/eastbournecottage/venv/lib/python3.8/site-packages/flask/app.py", line 2447, in wsgi_app
    response = self.full_dispatch_request()
  File "/hdd/code/eastbournecottage/venv/lib/python3.8/site-packages/flask/app.py", line 1952, in full_dispatch_request
    rv = self.handle_user_exception(e)
  File "/hdd/code/eastbournecottage/venv/lib/python3.8/site-packages/flask/app.py", line 1821, in handle_user_exception
    reraise(exc_type, exc_value, tb)
  File "/hdd/code/eastbournecottage/venv/lib/python3.8/site-packages/flask/_compat.py", line 39, in reraise
    raise value
  File "/hdd/code/eastbournecottage/venv/lib/python3.8/site-packages/flask/app.py", line 1950, in full_dispatch_request
    rv = self.dispatch_request()
  File "/hdd/code/eastbournecottage/venv/lib/python3.8/site-packages/flask/app.py", line 1936, in dispatch_request
    return self.view_functions[rule.endpoint](**req.view_args)
  File "/hdd/code/eastbournecottage/venv/lib/python3.8/site-packages/flask_login/utils.py", line 272, in decorated_view
    return func(*args, **kwargs)
  File "/hdd/code/eastbournecottage/app/routes.py", line 708, in set_bookings
    price_per_dog = db.session.query(Price_List_Settings).first().price_per_dog,
  File "/hdd/code/eastbournecottage/venv/lib/python3.8/site-packages/sqlalchemy/orm/query.py", line 3397, in first
    ret = list(self[0:1])
  File "/hdd/code/eastbournecottage/venv/lib/python3.8/site-packages/sqlalchemy/orm/query.py", line 3171, in __getitem__
    return list(res)
  File "/hdd/code/eastbournecottage/venv/lib/python3.8/site-packages/sqlalchemy/orm/query.py", line 3502, in __iter__
    self.session._autoflush()
  File "/hdd/code/eastbournecottage/venv/lib/python3.8/site-packages/sqlalchemy/orm/session.py", line 1628, in _autoflush
    util.raise_(e, with_traceback=sys.exc_info()[2])
  File "/hdd/code/eastbournecottage/venv/lib/python3.8/site-packages/sqlalchemy/util/compat.py", line 178, in raise_
    raise exception
  File "/hdd/code/eastbournecottage/venv/lib/python3.8/site-packages/sqlalchemy/orm/session.py", line 1617, in _autoflush
    self.flush()
  File "/hdd/code/eastbournecottage/venv/lib/python3.8/site-packages/sqlalchemy/orm/session.py", line 2523, in flush
    self._flush(objects)
  File "/hdd/code/eastbournecottage/venv/lib/python3.8/site-packages/sqlalchemy/orm/session.py", line 2664, in _flush
    transaction.rollback(_capture_exception=True)
  File "/hdd/code/eastbournecottage/venv/lib/python3.8/site-packages/sqlalchemy/util/langhelpers.py", line 68, in __exit__
    compat.raise_(
  File "/hdd/code/eastbournecottage/venv/lib/python3.8/site-packages/sqlalchemy/util/compat.py", line 178, in raise_
    raise exception
  File "/hdd/code/eastbournecottage/venv/lib/python3.8/site-packages/sqlalchemy/orm/session.py", line 2624, in _flush
    flush_context.execute()
  File "/hdd/code/eastbournecottage/venv/lib/python3.8/site-packages/sqlalchemy/orm/unitofwork.py", line 422, in execute
    rec.execute(self)
  File "/hdd/code/eastbournecottage/venv/lib/python3.8/site-packages/sqlalchemy/orm/unitofwork.py", line 586, in execute
    persistence.save_obj(
  File "/hdd/code/eastbournecottage/venv/lib/python3.8/site-packages/sqlalchemy/orm/persistence.py", line 239, in save_obj
    _emit_insert_statements(
  File "/hdd/code/eastbournecottage/venv/lib/python3.8/site-packages/sqlalchemy/orm/persistence.py", line 1135, in _emit_insert_statements
    result = cached_connections[connection].execute(
  File "/hdd/code/eastbournecottage/venv/lib/python3.8/site-packages/sqlalchemy/engine/base.py", line 1014, in execute
    return meth(self, multiparams, params)
  File "/hdd/code/eastbournecottage/venv/lib/python3.8/site-packages/sqlalchemy/sql/elements.py", line 298, in _execute_on_connection
    return connection._execute_clauseelement(self, multiparams, params)
  File "/hdd/code/eastbournecottage/venv/lib/python3.8/site-packages/sqlalchemy/engine/base.py", line 1127, in _execute_clauseelement
    ret = self._execute_context(
  File "/hdd/code/eastbournecottage/venv/lib/python3.8/site-packages/sqlalchemy/engine/base.py", line 1317, in _execute_context
    self._handle_dbapi_exception(
  File "/hdd/code/eastbournecottage/venv/lib/python3.8/site-packages/sqlalchemy/engine/base.py", line 1511, in _handle_dbapi_exception
    util.raise_(
  File "/hdd/code/eastbournecottage/venv/lib/python3.8/site-packages/sqlalchemy/util/compat.py", line 178, in raise_
    raise exception
  File "/hdd/code/eastbournecottage/venv/lib/python3.8/site-packages/sqlalchemy/engine/base.py", line 1277, in _execute_context
    self.dialect.do_execute(
  File "/hdd/code/eastbournecottage/venv/lib/python3.8/site-packages/sqlalchemy/engine/default.py", line 593, in do_execute
    cursor.execute(statement, parameters)
  File "/hdd/code/eastbournecottage/venv/lib/python3.8/site-packages/pymysql/cursors.py", line 163, in execute
    result = self._query(query)
  File "/hdd/code/eastbournecottage/venv/lib/python3.8/site-packages/pymysql/cursors.py", line 321, in _query
    conn.query(q)
  File "/hdd/code/eastbournecottage/venv/lib/python3.8/site-packages/pymysql/connections.py", line 505, in query
    self._affected_rows = self._read_query_result(unbuffered=unbuffered)
  File "/hdd/code/eastbournecottage/venv/lib/python3.8/site-packages/pymysql/connections.py", line 724, in _read_query_result
    result.read()
  File "/hdd/code/eastbournecottage/venv/lib/python3.8/site-packages/pymysql/connections.py", line 1069, in read
    first_packet = self.connection._read_packet()
  File "/hdd/code/eastbournecottage/venv/lib/python3.8/site-packages/pymysql/connections.py", line 676, in _read_packet
    packet.raise_for_error()
  File "/hdd/code/eastbournecottage/venv/lib/python3.8/site-packages/pymysql/protocol.py", line 223, in raise_for_error
    err.raise_mysql_exception(self._data)
  File "/hdd/code/eastbournecottage/venv/lib/python3.8/site-packages/pymysql/err.py", line 107, in raise_mysql_exception
    raise errorclass(errno, errval)
sqlalchemy.exc.DataError: (raised as a result of Query-invoked autoflush; consider using a session.no_autoflush block if this flush is occurring prematurely)
(pymysql.err.DataError) (1265, "Data truncated for column 'invoice_status' at row 1")
[SQL: INSERT INTO billing (booking_id, amount, date, invoice_due_date, transaction_type, note, invoice_reference, payment_reference, credit_note_reference, debit_note_reference, invoice_status, linked_invoice_id, first_invoice, last_reminder, percentage_due) VALUES (%(booking_id)s, %(amount)s, %(date)s, %(invoice_due_date)s, %(transaction_type)s, %(note)s, %(invoice_reference)s, %(payment_reference)s, %(credit_note_reference)s, %(debit_note_reference)s, %(invoice_status)s, %(linked_invoice_id)s, %(first_invoice)s, %(last_reminder)s, %(percentage_due)s)]
[parameters: {'booking_id': 67, 'amount': Decimal('300.00'), 'date': None, 'invoice_due_date': datetime.date(2021, 10, 14), 'transaction_type': 'INVOICE', 'note': None, 'invoice_reference': 5, 'payment_reference': None, 'credit_note_reference': None, 'debit_note_reference': None, 'invoice_status': 'ACCEPTED', 'linked_invoice_id': None, 'first_invoice': 0, 'last_reminder': None, 'percentage_due': Decimal('30.00')}]
(Background on this error at: http://sqlalche.me/e/13/9h9h)
2021-07-15 14:39:53,111 INFO: eastbourne startup [in /hdd/code/eastbournecottage/app/__init__.py:31]
2021-07-15 14:39:53,171 INFO: eastbourne startup [in /hdd/code/eastbournecottage/app/__init__.py:31]
2021-07-15 14:39:53,179 INFO: eastbourne startup [in /hdd/code/eastbournecottage/app/__init__.py:31]
2021-07-15 14:39:53,263 INFO: eastbourne startup [in /hdd/code/eastbournecottage/app/__init__.py:31]
2021-07-15 22:38:24,993 INFO: eastbourne startup [in /hdd/code/eastbournecottage/app/__init__.py:31]
2021-07-15 22:38:25,040 INFO: eastbourne startup [in /hdd/code/eastbournecottage/app/__init__.py:31]
2021-07-15 22:38:25,054 INFO: eastbourne startup [in /hdd/code/eastbournecottage/app/__init__.py:31]
2021-07-15 22:38:25,116 INFO: eastbourne startup [in /hdd/code/eastbournecottage/app/__init__.py:31]
2021-07-15 23:10:53,322 INFO: eastbourne startup [in /hdd/code/eastbournecottage/app/__init__.py:31]
